<?xml version="1.0" ?>
<!-- =================================================================================== -->
<!-- |    This document was autogenerated by xacro from /home/subash/ros2_ws/src/my_robot_description/urdf/arm_base.urdf.xacro | -->
<!-- |    EDITING THIS FILE BY HAND IS NOT RECOMMENDED                                 | -->
<!-- =================================================================================== -->
<robot>
  <link name="arm_base_link">
    <visual>
      <geometry>
        <box size="0.1 0.1 0.02"/>
      </geometry>
      <origin rpy="0 0 0" xyz="0 0 0.01"/>
      <material name="orange"/>
    </visual>
  </link>
  <link name="forearm_link">
    <visual>
      <geometry>
        <cylinder length="0.3" radius="0.02"/>
      </geometry>
      <origin rpy="0 0 0" xyz="0 0 0.15"/>
      <material name="yellow"/>
    </visual>
  </link>
  <link name="hand_link">
    <visual>
      <geometry>
        <cylinder length="0.3" radius="0.02"/>
      </geometry>
      <origin rpy="0 0 0" xyz="0 0 0.15"/>
      <material name="orange"/>
    </visual>
  </link>
  <joint name="arm_base_forearm_joint" type="revolute">
    <parent link="arm_base_link"/>
    <child link="forearm_link"/>
    <origin rpy="0 0 0" xyz="0 0 0.02"/>
    <axis xyz="0 1 0"/>
    <limit effort="100" lower="0" upper="1.5707963267948966" velocity="100"/>
  </joint>
  <joint name="forearm_hand_joint" type="revolute">
    <parent link="forearm_link"/>
    <child link="hand_link"/>
    <origin rpy="0 0 0" xyz="0 0 0.3"/>
    <axis xyz="0 1 0"/>
    <limit effort="100" lower="0" upper="1.5707963267948966" velocity="100"/>
  </joint>
  <material name="orange">
    <color rgba="1 0.5 0 1"/>
  </material>
  <material name="green">
    <color rgba="0 0 0.5 1"/>
  </material>
  <material name="red">
    <color rgba="0.5 0 0 1"/>
  </material>
  <material name="black">
    <color rgba="0 0 0 1"/>
  </material>
</robot>
